Workbook

Sheet Reference
B2: Reference number | C2: First author | E2: Publication year | F2: Title
C3: First name | D3: Last name
B4: 1 | C4: Ayman | D4: Elshkaki | E4: 2019 | F4: Energy-material nexus: The impacts of national and international energy scenarios on critical metals use in China up to 2050 and their global implications
B5: 2 | C5: Donghui | D5: Liu | E5: 2019 | F5: Supply and demand response trends of lithium resources driven by the demand of emerging renewable energy technologies in China
B6: 3 | C6: Takuma | D6: Watari | E6: 2019 | F6: Total Material Requirement for the Global Energy Transition to 2050: A focus on transport and electricity
B7: 4 | C7: Shivenes | D7: Shammugam | E7: 2019 | F7: Raw metal needs and supply risks for the development of wind energy in Germany until 2050
B8: 5 | C8: Emmanuel | D8: Hache | E8: 2019 | F8: Critical raw materials and transportation sector electrification: A detailed bottom-up analysis in world transport
B9: 6 | C9: Tomer | D9: Fishman | E9: 2019 | F9: Impact of the establishment of US offshore wind power on neodymium flows
B10: 7 | C10: Xiang-Yang | D10: Li | E10: 2019 | F10: Scenarios of rare earth elements demand driven by automotive electrification in China: 2018–2030
B11: 8 | C11: Vincent | D11: Moreau | E11: 2019 | F11: Enough Metals? Resource Constraints to Supply a Fully Renewable Energy System
B12: 9 | C12: Antoine | D12: Beylot | E12: 2019 | F12: Mineral raw material requirements and associated climate-change impacts of the French energy transition by 2050
B13: 10 | C13: Xin | D13: Sun | E13: 2018 | F13: The Dynamic Equilibrium Mechanism of Regional Lithium Flow for Transportation Electrificatio
B14: 11 | C14: Koji | D14: Tokimatsu | E14: 2018 | F14: Energy modeling approach to the global energy-mineral nexus: Exploring metal requirements and the well-below 2 °C target with 100 percent renewable energy
B15: 12 | C15: Alicia | D15: Valero | E15: 2018 | F15: Global material requirements for the energy transition. An exergy flow analysis of decarbonisation pathways
... B91: 88 | C91: Bjorn | D91: Andersson | E91: 1998 | F91: Material constraints for thin-film solar cells

Sheet Overview
B2: Reference number | C2: Last name of the first author | D2: Period | E2: Geographical boundary | F2: Considered technologies | Q2: Metal linkage
F3: Solar PV (c-Si, CIGS, CdTe) | G3: Wind | H3: EV | I3: Fuel cells | J3: Solar CSP | K3: Nuclear | L3: Geothermal | M3: Biomass | N3: CCS | O3: Storage batteries | P3: Others
B4: 1 | C4: Elshkaki | D4: 2050 | E4: China | F4: 1 | G4: 1 | J4: 1 | K4: 1 | L4: 1 | M4: 1
B5: 2 | C5: Liu | D5: 2110 | E5: China | H5: 1 | O5: 1
B6: 3 | C6: Watari | D6: 2050 | E6: World | F6: 1 | G6: 1 | H6: 1 | I6: 1 | J6: 1 | K6: 1 | L6: 1 | M6: 1 | N6: 1
B7: 4 | C7: Shammugam | D7: 2050 | E7: Germany | G7: 1
B8: 5 | C8: Hache | D8: 2050 | E8: World | H8: 1 | P8: 1
B9: 6 | C9: Fishman | D9: 2050 | E9: US | G9: 1
B10: 7 | C10: Li | D10: 2030 | E10: China | H10: 1 | I10: 1
B11: 8 | C11: Moreau | D11: 2050 | E11: World | F11: 1 | G11: 1 | J11: 1 | L11: 1 | M11: 1 | O11: 1
B12: 9 | C12: Beylot | D12: 2050 | E12: France | F12: 1 | G12: 1 | K12: 1
B13: 10 | C13: Sun | D13: 2050 | E13: China | H13: 1 | O13: 1 | P13: 1
B14: 11 | C14: Tokimatsu | D14: 2050 | E14: World | F14: 1 | G14: 1 | H14: 1 | I14: 1 | K14: 1 | L14: 1 | M14: 1 | N14: 1
B15: 12 | C15: Valero | D15: 2050 | E15: World | F15: 1 | G15: 1 | H15: 1 | J15: 1 | K15: 1 | L15: 1 | P15: 1
B16: 13 | C16: Valero | D16: 2050 | E16: World | F16: 1 | G16: 1 | H16: 1 | J16: 1 | P16: 1
B17: 14 | C17: Månberger | D17: 2060 | E17: World | F17: 1 | G17: 1 | H17: 1 | I17: 1 | J17: 1
B18: 15 | C18: Li | D18: 2050 | E18: World | F18: 1 | P18: 1
B19: 16 | C19: Watari | D19: 2060 | E19: World | F19: 1 | G19: 1 | H19: 1 | I19: 1 | P19: 1
B20: 17 | C20: Imholte | D20: 2030 | E20: US | G20: 1 | P20: 1
B21: 18 | C21: Deetman | D21: 2050 | E21: World | F21: 1 | G21: 1 | H21: 1 | I21: 1 | J21: 1 | K21: 1 | M21: 1 | N21: 1 | P21: 1
B22: 19 | C22: Ziemann | D22: 2050 | E22: World | H22: 1 | P22: 1
B23: 20 | C23: de Koning | D23: 2050 | E23: World | F23: 1 | G23: 1 | H23: 1 | I23: 1 | K23: 1 | N23: 1 | P23: 1
B24: 21 | C24: Fishman | D24: 2050 | E24: US | H24: 1
B25: 22 | C25: Schipper | D25: 2100 | E25: World | F25: 1 | G25: 1 | H25: 1 | J25: 1 | K25: 1 | L25: 1 | M25: 1 | N25: 1 | O25: 1 | P25: 1
B26: 23 | C26: Harvey | D26: 2100 | E26: World | H26: 1 | I26: 1 | P26: 1
B27: 24 | C27: Hun Choi | D27: 2050 | E27: World | F27: 1 | P27: 1 | Q27: 1
B28: 25 | C28: Zhou | D28: 2030 | E28: World | G28: 1 | H28: 1 | P28: 1
B29: 26 | C29: Olivetti | D29: 2025 | E29: World | H29: 1 | P29: 1
B30: 27 | C30: Tokimatsu | D30: 2100 | E30: World | F30: 1 | G30: 1 | H30: 1 | K30: 1 | L30: 1 | M30: 1 | N30: 1
B31: 28 | C31: Davidsson | D31: 2070 | E31: World | F31: 1
B32: 29 | C32: Vidal | D32: 2050 | E32: World | F32: 1 | G32: 1 | J32: 1 | K32: 1
B33: 30 | C33: Martin | D33: 2020 | E33: World | H33: 1 | P33: 1
B34: 31 | C34: Jasiński | D34: 2070 | E34: World | H34: 1 | I34: 1 | P34: 1
B35: 32 | C35: Busch | D35: 2050 | E35: UK | H35: 1 | I35: 1 | O35: 1
B36: 33 | C36: Pavel | D36: 2020 | E36: World | H36: 1
B37: 34 | C37: Pehlken | D37: 2050 | E37: World | H37: 1
B38: 35 | C38: Ulrik Sverdrup | D38: 2250 | E38: World | H38: 1 | P38: 1
B39: 36 | C39: Zhang | D39: 2030 | E39: World | H39: 1 | I39: 1
B40: 37 | C40: Nassar | D40: 2040 | E40: US | F40: 1 | G40: 1
B41: 38 | C41: Hun Choi | D41: 2050 | E41: World | F41: 1 | P41: 1 | Q41: 1
...

Sheet Life cycle&efficiency strategy
B2: Reference number | C2: Last name of the first author | D2: Life cycle/supply chain | J2: Material efficiency strategies
D3: Extraction/ processing | E3: Manufacturing | F3: Waste management | G3: Trade | H3: Environment | I3: Social | J3: Recycle | K3: Reduce | L3: Reuse | M3: Remanufacturing | N3: Lifetime extension
B4: 1 | C4: Elshkaki | D4: 1 | E4: 1 | F4: 1 | J4: 1 | K4: 1
B5: 2 | C5: Liu | D5: 1 | E5: 1 | F5: 1 | G5: 1 | J5: 1
B6: 3 | C6: Watari | D6: 1 | E6: 1 | F6: 1 | H6: 1 | J6: 1
B7: 4 | C7: Shammugam | D7: 1 | E7: 1 | F7: 1 | J7: 1 | K7: 1
B8: 5 | C8: Hache | E8: 1 | G8: 1 | K8: 1
B9: 6 | C9: Fishman | D9: 1 | E9: 1 | F9: 1 | J9: 1 | K9: 1
B10: 7 | C10: Li | E10: 1 | K10: 1
B11: 8 | C11: Moreau | D11: 1 | E11: 1 | F11: 1 | J11: 1
B12: 9 | C12: Beylot | E12: 1 | H12: 1
B13: 10 | C13: Sun | D13: 1 | E13: 1 | F13: 1 | G13: 1 | J13: 1
B14: 11 | C14: Tokimatsu | E14: 1
B15: 12 | C15: Valero | D15: 1 | E15: 1 | F15: 1 | J15: 1
B16: 13 | C16: Valero | D16: 1 | E16: 1 | F16: 1 | J16: 1
B17: 14 | C17: Månberger | D17: 1 | E17: 1 | F17: 1 | J17: 1 | K17: 1
B18: 15 | C18: Li | D18: 1 | E18: 1 | F18: 1 | J18: 1 | K18: 1 | N18: 1
B19: 16 | C19: Watari | D19: 1 | E19: 1 | F19: 1 | J19: 1 | K19: 1
B20: 17 | C20: Imholte | D20: 1 | E20: 1 | G20: 1
B21: 18 | C21: Deetman | E21: 1
B22: 19 | C22: Ziemann | D22: 1 | E22: 1 | F22: 1 | J22: 1
B23: 20 | C23: de Koning | E23: 1
B24: 21 | C24: Fishman | D24: 1 | E24: 1 | F24: 1 | J24: 1 | K24: 1
B25: 22 | C25: Schipper | D25: 1 | E25: 1 | F25: 1 | J25: 1
B26: 23 | C26: Harvey | D26: 1 | E26: 1 | F26: 1 | J26: 1 | K26: 1
B27: 24 | C27: Hun Choi | D27: 1 | E27: 1
B28: 25 | C28: Zhou | D28: 1 | E28: 1
B29: 26 | C29: Olivetti | D29: 1 | E29: 1
B30: 27 | C30: Tokimatsu | E30: 1
B31: 28 | C31: Davidsson | D31: 1 | E31: 1 | F31: 1 | J31: 1 | K31: 1
B32: 29 | C32: Vidal | D32: 1 | E32: 1 | F32: 1 | J32: 1
B33: 30 | C33: Martin | E33: 1
B34: 31 | C34: Jasiński | D34: 1 | E34: 1 | F34: 1 | J34: 1 | K34: 1
B35: 32 | C35: Busch | D35: 1 | E35: 1 | F35: 1 | J35: 1 | L35: 1
B36: 33 | C36: Pavel | E36: 1 | K36: 1
B37: 34 | C37: Pehlken | D37: 1 | E37: 1 | F37: 1 | J37: 1
B38: 35 | C38: Ulrik Sverdrup | D38: 1 | E38: 1 | F38: 1 | J38: 1 | N38: 1
B39: 36 | C39: Zhang | E39: 1 | K39: 1
B40: 37 | C40: Nassar | D40: 1 | E40: 1 | F40: 1 | J40: 1 | K40: 1
B41: 38 | C41: Hun Choi | D41: 1 | E41: 1 | F41: 1 | J41: 1 | K41: 1
...

Sheet Predicted demand summary
B2: Categories | C2: End-uses | E2: Year | F2: In | G2: Ag | H2: Pt | I2: Se | J2: Pb | K2: Cd | L2: Cr | M2: Te | N2: Sn | O2: Zn | P2: Mo | Q2: Dy | R2: Mn | S2: Nd | T2: Co | U2: Ge | V2: Ga | W2: Cu | X2: Ta | Y2: Ni | Z2: Li | AA2: Si
B3: Data points (-) | C3: Low-carbon technologies | E3: 2030 | F3: 16 | G3: 12 | H3: 9 | I3: 11 | J3: 0 | K3: 7 | L3: 2 | M3: 18 | N3: 1 | O3: 2 | P3: 1 | Q3: 16 | R3: 3 | S3: 15 | T3: 13 | U3: 2 | V3: 10 | W3: 9 | X3: 3 | Y3: 7 | Z3: 18 | AA3: 4
E4: 2050 | F4: 18 | G4: 12 | H4: 9 | I4: 11 | J4: 3 | K4: 8 | L4: 2 | M4: 18 | N4: 1 | O4: 2 | P4: 1 | Q4: 15 | R4: 3 | S4: 14 | T4: 13 | U4: 2 | V4: 10 | W4: 10 | X4: 3 | Y4: 7 | Z4: 21 | AA4: 0
C5: All | E5: 2030 | F5: 10 | G5: 5 | H5: 5 | I5: 5 | J5: 0 | K5: 3 | L5: 0 | M5: 5 | N5: 1 | O5: 0 | P5: 1 | Q5: 11 | R5: 1 | S5: 9 | T5: 5 | U5: 1 | V5: 4 | W5: 4 | X5: 3 | Y5: 3 | Z5: 13 | AA5: 1
E6: 2050 | F6: 10 | G6: 5 | H6: 5 | I6: 4 | J6: 2 | K6: 3 | L6: 2 | M6: 4 | N6: 1 | O6: 2 | P6: 1 | Q6: 10 | R6: 1 | S6: 7 | T6: 5 | U6: 1 | V6: 4 | W6: 6 | X6: 3 | Y6: 3 | Z6: 15 | AA6: 0
B7: Estimated value (kt) | C7: Low-carbon technologies | D7: Max | E7: 2030 | F7: 6.5 | G7: 12 | H7: 0.25 | I7: 25 | J7: NA | K7: 22 | L7: 1100 | M7: 24 | N7: 35 | O7: 850 | P7: 15 | Q7: 13 | R7: 1100 | S7: 150 | T7: 350 | U7: 0.3 | V7: 1.3 | W7: 9000 | X7: 2.3 | Y7: 1200 | Z7: 600 | AA7: 1350
D8: Min | F8: 0.1 | G8: 0.8 | H8: 0.001 | I8: 0.2 | J8: NA | K8: 0.28 | L8: 500 | M8: 0.2 | N8: NA | O8: 520 | P8: NA | Q8: 0.2 | R8: 200 | S8: 1.5 | T8: 3 | U8: 0.3 | V8: 0.01 | W8: 1000 | X8: 0.3 | Y8: 200 | Z8: 15 | AA8: 450
D9: Max | E9: 2050 | F9: 8 | G9: 26 | H9: 1.3 | I9: 25 | J9: 2000 | K9: 22 | L9: 3270 | M9: 24 | N9: 70 | O9: 4160 | P9: 25 | Q9: 45 | R9: 4000 | S9: 270 | T9: 1280 | U9: 2.5 | V9: 1.3 | W9: 17200 | X9: 3.2 | Y9: 4500 | Z9: 2000 | AA9: 1830
D10: Min | F10: 0.03 | G10: 0.8 | H10: 0.006 | I10: 0.2 | J10: 1400 | K10: 0.5 | L10: 200 | M10: 0.25 | N10: NA | O10: 8701 | P10: NA | Q10: 0.05 | R10: 500 | S10: 0.09 | T10: 6 | U10: 2.5 | V10: 0.02 | W10: 1000 | X10: 0.65 | Y10: 200 | Z10: 0.4 | AA10: 820
C11: All | D11: Max | E11: 2030 | F11: 8.25 | G11: 60 | H11: 0.5 | I11: 23 | J11: NA | K11: 50 | L11: NA | M11: 20.8 | N11: 300 | O11: NA | P11: 270 | Q11: 15 | R11: 18000 | S11: 220 | T11: 440 | U11: 0.5 | V11: 2.8 | W11: 57000 | X11: 4.7 | Y11: 4600 | Z11: 700 | AA11: 12200
D12: Min | F12: 0.85 | G12: 28 | H12: 0.28 | I12: 1.7 | J12: NA | K12: 30 | L12: NA | M12: 0.3 | N12: NA | O12: NA | P12: NA | Q12: 3.5 | R12: NA | S12: 40 | T12: 200 | U12: NA | V12: 0.5 | W12: 30000 | X12: 1.5 | Y12: 3200 | Z12: 60 | AA12: NA
D13: Max | E13: 2050 | F13: 9 | G13: 127 | H13: 1.7 | I13: 28 | J13: 7650 | K13: 93 | L13: 22490 | M13: 17 | N13: 340 | O13: 14580 | P13: 280 | Q13: 50 | R13: 18000 | S13: 240 | T13: 1260 | U13: 2.8 | V13: 5.25 | W13: 120000 | X13: 6.6 | Y13: 10000 | Z13: 1630 | AA13: NA
D14: Min | F14: 1.2 | G14: 38 | H14: 0.7 | I14: 2.1 | J14: 7460 | K14: 60 | L14: 22360 | M14: 1.6 | N14: NA | O14: 14480 | P14: NA | Q14: 3.23 | R14: NA | S14: 60 | T14: 420 | U14: NA | V14: 0.85 | W14: 27000 | X14: 1.8 | Y14: 4500 | Z14: 200 | AA14: NA
B15: Growth rate based on 2015 (-) | C15: Low-carbon technologies | D15: Max | E15: 2030 | F15: 8.4525358 | G15: 0.47808765 | H15: 1.3038422 | I15: 11.363636 | J15: NA | K15: 0.94827586 | L15: 0.11752137 | M15: 143.71257 | N15: 0.12027491 | O15: 0.06640625 | P15: 0.063829787 | Q15: 7.3989755 | R15: 0.062857143 | S15: 7.3803413 | T15: 2.7777778 | U15: 1.875 | V15: 2.771855 | W15: 0.47120419 | X15: 1.965812 | Y15: 0.52631579 | Z15: 19.047619 | AA15: 0.17693316
D16: Min | F16: 0.13003901 | G16: 0.03187251 | H16: 0.0052153686 | I16: 0.090909091 | J16: NA | K16: 0.012068966 | L16: 0.053418803 | M16: 1.1976048 | N16: NA | O16: 0.040625 | P16: NA | Q16: 0.11383039 | R16: 0.011428571 | S16: 0.073803413 | T16: 0.023809524 | U16: 1.875 | V16: 0.021321962 | W16: 0.052356021 | X16: 0.25641026 | Y16: 0.087719298 | Z16: 0.47619048 | AA16: 0.05897772
D17: Max | E17: 2050 | F17: 10.403121 | G17: 1.0358566 | H17: 6.7799792 | I17: 11.363636 | J17: 0.4040404 | K17: 0.94827586 | L17: 0.34935897 | M17: 143.71257 | N17: 0.24054983 | O17: 0.325 | P17: 0.10638298 | Q17: 25.611838 | R17: 0.22857143 | S17: 13.284614 | T17: 10.15873 | U17: 15.625 | V17: 2.771855 | W17: 0.90052356 | X17: 2.7350427 | Y17: 1.9736842 | Z17: 63.492063 | AA17: 0.23984273
D18: Min | F18: 0.039011704 | G18: 0.03187251 | H18: 0.031292212 | I18: 0.090909091 | J18: 0.28282828 | K18: 0.021551724 | L18: 0.021367521 | M18: 1.497006 | N18: NA | O18: 0.67976563 | P18: NA | Q18: 0.028457598 | R18: 0.028571429 | S18: 0.0044282048 | T18: 0.047619048 | U18: 15.625 | V18: 0.042643923 | W18: 0.052356021 | X18: 0.55555556 | Y18: 0.087719298 | Z18: 0.012698413 | AA18: 0.10747051
C19: All | D19: Max | E19: 2030 | F19: 10.728218 | G19: 2.3904382 | H19: 2.6076843 | I19: 10.454545 | J19: NA | K19: 2.1551724 | L19: NA | M19: 124.5509 | N19: 1.0309278 | O19: NA | P19: 1.1489362 | Q19: 8.5372795 | R19: 1.0285714 | S19: 10.824501 | T19: 3.4920635 | U19: 3.125 | V19: 5.9701493 | W19: 2.9842932 | X19: 4.017094 | Y19: 2.0175439 | Z19: 22.222222 | AA19: 1.5989515
D20: Min | F20: 1.1053316 | G20: 1.1155378 | H20: 1.4603032 | I20: 0.77272727 | J20: NA | K20: 1.2931034 | L20: NA | M20: 1.7964072 | N20: NA | O20: NA | P20: NA | Q20: 1.9920319 | R20: NA | S20: 1.968091 | T20: 1.5873016 | U20: NA | V20: 1.0660981 | W20: 1.5706806 | X20: 1.2820513 | Y20: 1.4035088 | Z20: 1.9047619 | AA20: NA
D21: Max | E21: 2050 | F21: 11.703511 | G21: 5.059761 | H21: 8.8661267 | I21: 12.727273 | J21: 1.5454545 | K21: 4.0086207 | L21: 2.4027778 | M21: 101.79641 | N21: 1.1683849 | O21: 1.1390625 | P21: 1.1914894 | Q21: 28.457598 | R21: 1.0285714 | S21: 11.808546 | T21: 10 | U21: 17.5 | V21: 11.19403 | W21: 6.2827225 | X21: 5.6410256 | Y21: 4.3859649 | Z21: 51.746032 | AA21: NA
D22: Min | F22: 1.5604681 | G22: 1.5139442 | H22: 3.6507581 | I22: 0.95454545 | J22: 1.5070707 | K22: 2.5862069 | L22: 2.3888889 | M22: 9.5808383 | N22: NA | O22: 1.13125 | P22: NA | Q22: 1.8383608 | R22: NA | S22: 2.9521365 | T22: 3.3333333 | U22: NA | V22: 1.8123667 | W22: 1.4136126 | X22: 1.5384615 | Y22: 1.9736842 | Z22: 6.3492063 | AA22: NA

Sheet In
A1: Unit: kt | E1: for low-carbon technologies
E2: for all end-uses
B4: Reference number | C4: Last name of the first author | D4: 2030 | E4: 2050 | F4: End-uses
B6: 3 | C6: =VLOOKUP(B6, Reference!$B:$D, 3, TRUE) -> Watari | D6: 0.24 | E6: 0.9 | F6: Solar PV (CIGS)
D7: 0.16 | E7: 0.4
B8: 13 | C8: =VLOOKUP(B8, Reference!$B:$D, 3, TRUE) -> Valero | D8: 0.35 | E8: 0.75
B9: 14 | C9: =VLOOKUP(B9, Reference!$B:$D, 3, TRUE) -> Månberger | D9: 0.4 | E9: 1
D10: 0.1 | E10: 0.1
B11: 16 | C11: =VLOOKUP(B11, Reference!$B:$D, 3, TRUE) -> Watari | D11: 1 | E11: 3.8
D12: 0.25 | E12: 0.7
B13: 20 | C13: =VLOOKUP(B13, Reference!$B:$D, 3, TRUE) -> de Koning | E13: 0.2
E14: 0.03
B15: 28 | C15: =VLOOKUP(B15, Reference!$B:$D, 3, TRUE) -> Davidsson | D15: 4.3 | E15: 4.3
D16: 1.1 | E16: 1.1
B17: 45 | C17: =VLOOKUP(B17, Reference!$B:$D, 3, TRUE) -> Elshkaki | D17: 0.2 | E17: 1.3
B18: 51 | C18: =VLOOKUP(B18, Reference!$B:$D, 3, TRUE) -> Stamp | D18: 6.5 | E18: 8
D19: 0.7 | E19: 4.2
B20: 60 | C20: =VLOOKUP(B20, Reference!$B:$D, 3, TRUE) -> Elshkaki | D20: 0.2 | E20: 1.3
B21: 61 | C21: =VLOOKUP(B21, Reference!$B:$D, 3, TRUE) -> Elshkaki | D21: 0.29 | E21: 0.43
B22: 62 | C22: =VLOOKUP(B22, Reference!$B:$D, 3, TRUE) -> Fizaine | D22: 0.4 | E22: 0.9
B23: 85 | C23: =VLOOKUP(B23, Reference!$B:$D, 3, TRUE) -> Fthenakis | D23: 0.3 | E23: 0.3
B24: 13 | C24: =VLOOKUP(B24, Reference!$B:$D, 3, TRUE) -> Valero | D24: 0.85 | E24: 1.2 | F24: All
B25: 16 | C25: =VLOOKUP(B25, Reference!$B:$D, 3, TRUE) -> Watari | D25: 2.5 | E25: 6.3
D26: 1.6 | E26: 3
B27: 20 | C27: =VLOOKUP(B27, Reference!$B:$D, 3, TRUE) -> de Koning | E27: 2
E28: 1.85
B29: 24 | C29: =VLOOKUP(B29, Reference!$B:$D, 3, TRUE) -> Hun Choi | D29: 5 | E29: 9
B30: 38 | C30: =VLOOKUP(B30, Reference!$B:$D, 3, TRUE) -> Hun Choi | D30: 1.5 | E30: 2.5
B31: 45 | C31: =VLOOKUP(B31, Reference!$B:$D, 3, TRUE) -> Elshkaki | D31: 1.5 | E31: 3.8
B32: 46 | C32: =VLOOKUP(B32, Reference!$B:$D, 3, TRUE) -> Kavlak | D32: 8.25
B33: 51 | C33: =VLOOKUP(B33, Reference!$B:$D, 3, TRUE) -> Stamp | D33: 7.2 | E33: 8.7
D34: 1.3 | E34: 4.9

Sheet Ag
A1: Unit: kt | E1: for low-carbon technologies
E2: for all end-uses
B4: Reference number | C4: Last name of the first author | D4: 2030 | E4: 2050 | F4: End-uses
B6: 3 | C6: =VLOOKUP(B6, Reference!$B:$D, 3, TRUE) -> Watari | D6: 3.7 | E6: 9.7 | F6: Solar PV (c-Si) and CSP
D7: 2.2 | E7: 4.1
B8: 13 | C8: =VLOOKUP(B8, Reference!$B:$D, 3, TRUE) -> Valero | D8: 9 | E8: 16 | F8: Solar PV (c-Si), CSP and EVs
B9: 14 | C9: =VLOOKUP(B9, Reference!$B:$D, 3, TRUE) -> Månberger | D9: 1 | E9: 4 | F9: Solar PV (c-Si) and CSP
D10: 0.8 | E10: 0.8
B11: 15 | C11: =VLOOKUP(B11, Reference!$B:$D, 3, TRUE) -> Li | D11: 9 | E11: 12 | F11: Solar PV (c-Si)
B12: 16 | C12: =VLOOKUP(B12, Reference!$B:$D, 3, TRUE) -> Watari | D12: 9.8 | E12: 26
D13: 6.4 | E13: 12
B14: 28 | C14: =VLOOKUP(B14, Reference!$B:$D, 3, TRUE) -> Davidsson | D14: 12 | E14: 12
D15: 3 | E15: 1
B16: 45 | C16: =VLOOKUP(B16, Reference!$B:$D, 3, TRUE) -> Elshkaki | D16: 5 | E16: 25
B17: 60 | C17: =VLOOKUP(B17, Reference!$B:$D, 3, TRUE) -> Elshkaki | D17: 6.7 | E17: 5.3 | F17: Solar PV (c-Si) and CSP
B18: 13 | C18: =VLOOKUP(B18, Reference!$B:$D, 3, TRUE) -> Valero | D18: 28 | E18: 38 | F18: All
B19: 15 | C19: =VLOOKUP(B19, Reference!$B:$D, 3, TRUE) -> Li | D19: 40 | E19: 58
B20: 16 | C20: =VLOOKUP(B20, Reference!$B:$D, 3, TRUE) -> Watari | D20: 60 | E20: 127
D21: 57 | E21: 112
B22: 45 | C22: =VLOOKUP(B22, Reference!$B:$D, 3, TRUE) -> Elshkaki | D22: 40 | E22: 105

Sheet Pt
A1: Unit: kt | E1: for low-carbon technologies
E2: for all end-uses
B4: Reference number | C4: Last name of the first author | D4: 2030 | E4: 2050 | F4: End-uses
B6: 3 | C6: =VLOOKUP(B6, Reference!$B:$D, 3, TRUE) -> Watari | D6: 0.02 | E6: 0.07 | F6: Fuel cells
D7: 0.002 | E7: 0.006
B8: 14 | C8: =VLOOKUP(B8, Reference!$B:$D, 3, TRUE) -> Månberger | D8: 0.015 | E8: 0.04
D9: 0.001 | E9: 0.015
B10: 16 | C10: =VLOOKUP(B10, Reference!$B:$D, 3, TRUE) -> Watari | D10: 0.05 | E10: 0.2
D11: 0.004 | E11: 0.015
B12: 61 | C12: =VLOOKUP(B12, Reference!$B:$D, 3, TRUE) -> Elshkaki | D12: 0.25 | E12: 1.3
B13: 75 | C13: =VLOOKUP(B13, Reference!$B:$D, 3, TRUE) -> Alonso | D13: 0.1 | E13: 0.65
B14: 78 | C14: =VLOOKUP(B14, Reference!$B:$D, 3, TRUE) -> Sun | D14: 0.05 | E14: 0.4
B15: 16 | C15: =VLOOKUP(B15, Reference!$B:$D, 3, TRUE) -> Watari | D15: 0.4 | E15: 0.8 | F15: All
D16: 0.3 | E16: 0.7
B17: 61 | C17: =VLOOKUP(B17, Reference!$B:$D, 3, TRUE) -> Elshkaki | D17: 0.5 | E17: 1.7
B18: 75 | C18: =VLOOKUP(B18, Reference!$B:$D, 3, TRUE) -> Alonso | D18: 0.4 | E18: 1.15
B19: 78 | C19: =VLOOKUP(B19, Reference!$B:$D, 3, TRUE) -> Sun | D19: 0.28 | E19: 0.7

Sheet Se
A1: Unit: kt | E1: for low-carbon technologies
E2: for all end-uses
B4: Reference number | C4: Last name of the first author | D4: 2030 | E4: 2050 | F4: End-uses
B6: 3 | C6: =VLOOKUP(B6, Reference!$B:$D, 3, TRUE) -> Watari | D6: 0.47 | E6: 1.8 | F6: Solar PV (CIGS)
D7: 0.3 | E7: 0.8
B8: 13 | C8: =VLOOKUP(B8, Reference!$B:$D, 3, TRUE) -> Valero | D8: 0.25 | E8: 0.45
B9: 14 | C9: =VLOOKUP(B9, Reference!$B:$D, 3, TRUE) -> Månberger | D9: 1.2 | E9: 3
D10: 0.2 | E10: 0.2
B11: 16 | C11: =VLOOKUP(B11, Reference!$B:$D, 3, TRUE) -> Watari | D11: 5.3 | E11: 7.4
D12: 3.8 | E12: 1.3
B13: 28 | C13: =VLOOKUP(B13, Reference!$B:$D, 3, TRUE) -> Davidsson | D13: 25 | E13: 25
D14: 2.5 | E14: 2.5
B15: 45 | C15: =VLOOKUP(B15, Reference!$B:$D, 3, TRUE) -> Elshkaki | D15: 3 | E15: 3
B16: 60 | C16: =VLOOKUP(B16, Reference!$B:$D, 3, TRUE) -> Elshkaki | D16: 0.27 | E16: 2.1
B17: 13 | C17: =VLOOKUP(B17, Reference!$B:$D, 3, TRUE) -> Valero | D17: 1.7 | E17: 2.1 | F17: All
B18: 16 | C18: =VLOOKUP(B18, Reference!$B:$D, 3, TRUE) -> Watari | D18: 12 | E18: 13
D19: 3.8 | E19: 7
B20: 45 | C20: =VLOOKUP(B20, Reference!$B:$D, 3, TRUE) -> Elshkaki | D20: 23 | E20: 28
B21: 46 | C21: =VLOOKUP(B21, Reference!$B:$D, 3, TRUE) -> Kavlak | D21: 14.5

Sheet Pb
A1: Unit: kt | E1: for low-carbon technologies
E2: for all end-uses
B4: Reference number | C4: Last name of the first author | D4: 2030 | E4: 2050 | F4: End-uses
B6: 20 | C6: =VLOOKUP(B6, Reference!$B:$D, 3, TRUE) -> de Koning | E6: 2026 | F6: Solar PV and Nuclear
E7: 1810
B8: 60 | C8: =VLOOKUP(B8, Reference!$B:$D, 3, TRUE) -> Elshkaki | E8: 1435 | F8: Wind
B9: 20 | C9: =VLOOKUP(B9, Reference!$B:$D, 3, TRUE) -> de Koning | E9: 7653 | F9: All
E10: 7463

Sheet Cd
A1: Unit: kt | E1: for low-carbon technologies
E2: for all end-uses
B4: Reference number | C4: Last name of the first author | D4: 2030 | E4: 2050 | F4: End-uses
B6: 3 | C6: =VLOOKUP(B6, Reference!$B:$D, 3, TRUE) -> Watari | D6: 0.43 | E6: 1.15 | F6: Solar PV (CdTe)
D7: 0.28 | E7: 0.5
B8: 16 | C8: =VLOOKUP(B8, Reference!$B:$D, 3, TRUE) -> Watari | D8: 3.8 | E8: 14
D9: 0.92 | E9: 2.5
B10: 28 | C10: =VLOOKUP(B10, Reference!$B:$D, 3, TRUE) -> Davidsson | D10: 22 | E10: 22
D11: 2.8 | E11: 2.8
B12: 45 | C12: =VLOOKUP(B12, Reference!$B:$D, 3, TRUE) -> Elshkaki | D12: 2 | E12: 20
B13: 60 | C13: =VLOOKUP(B13, Reference!$B:$D, 3, TRUE) -> Elshkaki | E13: 0.55
B14: 16 | C14: =VLOOKUP(B14, Reference!$B:$D, 3, TRUE) -> Watari | D14: 49 | E14: 93 | F14: All
D15: 46 | E15: 81
B16: 45 | C16: =VLOOKUP(B16, Reference!$B:$D, 3, TRUE) -> Elshkaki | D16: 30 | E16: 60
B17: 56 | C17: =VLOOKUP(B17, Reference!$B:$D, 3, TRUE) -> Speirs | D17: 42.3

Sheet Cr
A1: Unit: kt | E1: for low-carbon technologies
E2: for all end-uses
B4: Reference number | C4: Last name of the first author | D4: 2030 | E4: 2050 | F4: End-uses
B6: 3 | C6: =VLOOKUP(B6, Reference!$B:$D, 3, TRUE) -> Watari | D6: 1105 | E6: 3271 | F6: Solar PV, Wind, CSP, CCS and Electric vehicles
D7: 502 | E7: 1190
B8: 20 | C8: =VLOOKUP(B8, Reference!$B:$D, 3, TRUE) -> de Koning | E8: 22357 | F8: All
E9: 22491

Sheet Te
A1: Unit: kt | E1: for low-carbon technologies
E2: for all end-uses
B4: Reference number | C4: Last name of the first author | D4: 2030 | E4: 2050 | F4: End-uses
B6: 3 | C6: =VLOOKUP(B6, Reference!$B:$D, 3, TRUE) -> Watari | D6: 0.5 | E6: 1.4 | F6: Solar PV (CdTe)
D7: 0.34 | E7: 0.64
B8: 13 | C8: =VLOOKUP(B8, Reference!$B:$D, 3, TRUE) -> Valero | D8: 0.75 | E8: 1.5
B9: 14 | C9: =VLOOKUP(B9, Reference!$B:$D, 3, TRUE) -> Månberger | D9: 0.7 | E9: 2.2
D10: 0.2 | E10: 0.25
B11: 16 | C11: =VLOOKUP(B11, Reference!$B:$D, 3, TRUE) -> Watari | D11: 4.4 | E11: 16
D12: 1 | E12: 2.9
B13: 28 | C13: =VLOOKUP(B13, Reference!$B:$D, 3, TRUE) -> Davidsson | D13: 24 | E13: 24
D14: 3 | E14: 3
B15: 45 | C15: =VLOOKUP(B15, Reference!$B:$D, 3, TRUE) -> Elshkaki | D15: 0.2 | E15: 2.5
B16: 54 | C16: =VLOOKUP(B16, Reference!$B:$D, 3, TRUE) -> Bustamante | D16: 4.5 | E16: 4.5
D17: 2 | E17: 4.5
B18: 58 | C18: =VLOOKUP(B18, Reference!$B:$D, 3, TRUE) -> Houari | D18: 1.8 | E18: 3.5
D19: 0.7 | E19: 1
B20: 60 | C20: =VLOOKUP(B20, Reference!$B:$D, 3, TRUE) -> Elshkaki | D20: 0.4 | E20: 2.7
B21: 77 | C21: =VLOOKUP(B21, Reference!$B:$D, 3, TRUE) -> Zuser | D21: 0.69 | E21: 1.1
B22: 85 | C22: =VLOOKUP(B22, Reference!$B:$D, 3, TRUE) -> Fthenakis | D22: 1.5 | E22: 1.5
D23: 1.2 | E23: 1.2
B24: 13 | C24: =VLOOKUP(B24, Reference!$B:$D, 3, TRUE) -> Valero | D24: 0.85 | E24: 1.6 | F24: All
B25: 16 | C25: =VLOOKUP(B25, Reference!$B:$D, 3, TRUE) -> Watari | D25: 4.7 | E25: 17
D26: 1.4 | E26: 3.4
B27: 45 | C27: =VLOOKUP(B27, Reference!$B:$D, 3, TRUE) -> Elshkaki | D27: 0.3 | E27: 2.7
B28: 46 | C28: =VLOOKUP(B28, Reference!$B:$D, 3, TRUE) -> Kavlak | D28: 20.8

Sheet Sn
A1: Unit: kt | E1: for low-carbon technologies
E2: for all end-uses
B4: Reference number | C4: Last name of the first author | D4: 2030 | E4: 2050 | F4: End-uses
B6: 13 | C6: =VLOOKUP(B6, Reference!$B:$D, 3, TRUE) -> Valero | D6: 35 | E6: 70 | F6: Solar PV
B7: 13 | C7: =VLOOKUP(B7, Reference!$B:$D, 3, TRUE) -> Valero | D7: 270 | E7: 310 | F7: All

Sheet Zn
A1: Unit: kt | E1: for low-carbon technologies
E2: for all end-uses
B4: Reference number | C4: Last name of the first author | D4: 2030 | E4: 2050 | F4: End-uses
B6: 3 | C6: =VLOOKUP(B6, Reference!$B:$D, 3, TRUE) -> Watari | D6: 849 | E6: 1590 | F6: Solar PV, Wind, CSP, Electric vehicles and Fuel cells
D7: 520 | E7: 869
B8: 20 | C8: =VLOOKUP(B8, Reference!$B:$D, 3, TRUE) -> de Koning | E8: 14580 | F8: All
E9: 14481

Sheet Mo
A1: Unit: kt | E1: for low-carbon technologies
E2: for all end-uses
B4: Reference number | C4: Last name of the first author | D4: 2030 | E4: 2050 | F4: End-uses
B6: 13 | C6: =VLOOKUP(B6, Reference!$B:$D, 3, TRUE) -> Valero | D6: 15 | E6: 25 | F6: Solar PV, CSP and Electric vehicles
B7: 13 | C7: =VLOOKUP(B7, Reference!$B:$D, 3, TRUE) -> Valero | D7: 270 | E7: 280 | F7: All

Sheet Dy
A1: Unit: kt | E1: for low-carbon technologies
E2: for all end-uses
B4: Reference number | C4: Last name of the first author | D4: 2030 | E4: 2050 | F4: End-uses
B6: 3 | C6: =VLOOKUP(B6, Reference!$B:$D, 3, TRUE) -> Watari | D6: 8.8 | E6: 30 | F6: Wind and electric vehicles
D7: 3.8 | E7: 13.7
B8: 13 | C8: =VLOOKUP(B8, Reference!$B:$D, 3, TRUE) -> Valero | D8: 3.9 | E8: 7.5
B9: 14 | C9: =VLOOKUP(B9, Reference!$B:$D, 3, TRUE) -> Månberger | D9: 1.7 | E9: 3.2
D10: 0.2 | E10: 0.2
B11: 16 | C11: =VLOOKUP(B11, Reference!$B:$D, 3, TRUE) -> Watari | D11: 4.4 | E11: 13
D12: 2.1 | E12: 7
B13: 20 | C13: =VLOOKUP(B13, Reference!$B:$D, 3, TRUE) -> de Koning | E13: 2.2 | F13: Wind
E14: 0.05
B15: 40 | C15: =VLOOKUP(B15, Reference!$B:$D, 3, TRUE) -> Schulze | D15: 3.8 | F15: Wind and electric vehicles
D16: 0.78
B17: 49 | C17: =VLOOKUP(B17, Reference!$B:$D, 3, TRUE) -> Elshkaki | D17: 3.3 | E17: 6 | F17: Wind
B18: 55 | C18: =VLOOKUP(B18, Reference!$B:$D, 3, TRUE) -> Habib | D18: 2 | E18: 17.5 | F18: Wind and electric vehicles
D19: 0.5 | E19: 4.5
B20: 60 | C20: =VLOOKUP(B20, Reference!$B:$D, 3, TRUE) -> Elshkaki | D20: 0.27 | E20: 2.1 | F20: Wind
B21: 66 | C21: =VLOOKUP(B21, Reference!$B:$D, 3, TRUE) -> Rademaker | D21: 0.46 | F21: Wind and electric vehicles
B22: 67 | C22: =VLOOKUP(B22, Reference!$B:$D, 3, TRUE) -> Hoenderdaal | D22: 13 | E22: 45
D23: 2.5 | E23: 5
B24: 13 | C24: =VLOOKUP(B24, Reference!$B:$D, 3, TRUE) -> Valero | D24: 5.5 | E24: 9 | F24: All
B25: 16 | C25: =VLOOKUP(B25, Reference!$B:$D, 3, TRUE) -> Watari | D25: 8 | E25: 19
D26: 5.9 | E26: 14
B27: 20 | C27: =VLOOKUP(B27, Reference!$B:$D, 3, TRUE) -> de Koning | E27: 5.35
E28: 3.23
B29: 25 | C29: =VLOOKUP(B29, Reference!$B:$D, 3, TRUE) -> Zhou | D29: 4
B30: 40 | C30: =VLOOKUP(B30, Reference!$B:$D, 3, TRUE) -> Schulze | D30: 10
D31: 6.6
B32: 49 | C32: =VLOOKUP(B32, Reference!$B:$D, 3, TRUE) -> Elshkaki | D32: 3.5 | E32: 8
B33: 55 | C33: =VLOOKUP(B33, Reference!$B:$D, 3, TRUE) -> Habib | D33: 7 | E33: 32
D34: 4 | E34: 11
B35: 67 | C35: =VLOOKUP(B35, Reference!$B:$D, 3, TRUE) -> Hoenderdaal | D35: 15 | E35: 50
D36: 6 | E36: 14

Sheet Mn
A1: Unit: kt | E1: for low-carbon technologies
E2: for all end-uses
B4: Reference number | C4: Last name of the first author | D4: 2030 | E4: 2050 | F4: End-uses
B6: 3 | C6: =VLOOKUP(B6, Reference!$B:$D, 3, TRUE) -> Watari | D6: 1105 | E6: 4089 | F6: Wind, CSP, Electric vehicles and Fuel cells
D7: 272 | E7: 1048
B8: 13 | C8: =VLOOKUP(B8, Reference!$B:$D, 3, TRUE) -> Valero | D8: 200 | E8: 500 | F8: CSP and Electric vehicles
B9: 13 | C9: =VLOOKUP(B9, Reference!$B:$D, 3, TRUE) -> Valero | D9: 18000 | E9: 18000 | F9: All

Sheet Nd
A1: Unit: kt | E1: for low-carbon technologies
E2: for all end-uses
B4: Reference number | C4: Last name of the first author | D4: 2030 | E4: 2050 | F4: End-uses
B6: 3 | C6: =VLOOKUP(B6, Reference!$B:$D, 3, TRUE) -> Watari | D6: 37 | E6: 123.5 | F6: Wind and Electric vehicles
D7: 16.8 | E7: 59
B8: 13 | C8: =VLOOKUP(B8, Reference!$B:$D, 3, TRUE) -> Valero | D8: 28 | E8: 55
B9: 14 | C9: =VLOOKUP(B9, Reference!$B:$D, 3, TRUE) -> Månberger | D9: 35 | E9: 80
D10: 5 | E10: 5
B11: 16 | C11: =VLOOKUP(B11, Reference!$B:$D, 3, TRUE) -> Watari | D11: 36 | E11: 102
D12: 17 | E12: 58
B13: 18 | C13: =VLOOKUP(B13, Reference!$B:$D, 3, TRUE) -> Deetman | D13: 150 | E13: 270
D14: 25 | E14: 34
B15: 20 | C15: =VLOOKUP(B15, Reference!$B:$D, 3, TRUE) -> de Koning | E15: 68
E16: 0.09
B17: 40 | C17: =VLOOKUP(B17, Reference!$B:$D, 3, TRUE) -> Schulze | D17: 66.8
D18: 10
B19: 55 | C19: =VLOOKUP(B19, Reference!$B:$D, 3, TRUE) -> Habib | D19: 15 | E19: 130
D20: 5 | E20: 25
B21: 60 | C21: =VLOOKUP(B21, Reference!$B:$D, 3, TRUE) -> Elshkaki | D21: 1.5 | E21: 12 | F21: Wind
B22: 66 | C22: =VLOOKUP(B22, Reference!$B:$D, 3, TRUE) -> Rademaker | D22: 1.8 | F22: Wind and Electric vehicles
B23: 13 | C23: =VLOOKUP(B23, Reference!$B:$D, 3, TRUE) -> Valero | D23: 42 | E23: 70 | F23: All
B24: 16 | C24: =VLOOKUP(B24, Reference!$B:$D, 3, TRUE) -> Watari | D24: 70 | E24: 163
D25: 52 | E25: 118
B26: 20 | C26: =VLOOKUP(B26, Reference!$B:$D, 3, TRUE) -> de Koning | E26: 125
E27: 58
B28: 25 | C28: =VLOOKUP(B28, Reference!$B:$D, 3, TRUE) -> Zhou | D28: 39
B29: 40 | C29: =VLOOKUP(B29, Reference!$B:$D, 3, TRUE) -> Schulze | D29: 194
D30: 71
B31: 55 | C31: =VLOOKUP(B31, Reference!$B:$D, 3, TRUE) -> Habib | D31: 70 | E31: 242
D32: 45 | E32: 100
B33: 66 | C33: =VLOOKUP(B33, Reference!$B:$D, 3, TRUE) -> Rademaker | D33: 220

Sheet Co
A1: Unit: kt | E1: for low-carbon technologies
E2: for all end-uses
B4: Reference number | C4: Last name of the first author | D4: 2030 | E4: 2050 | F4: End-uses
B6: 3 | C6: =VLOOKUP(B6, Reference!$B:$D, 3, TRUE) -> Watari | D6: 229.5 | E6: 1280 | F6: Electric vehicles
D7: 64.8 | E7: 277
B8: 13 | C8: =VLOOKUP(B8, Reference!$B:$D, 3, TRUE) -> Valero | D8: 120 | E8: 310
B9: 14 | C9: =VLOOKUP(B9, Reference!$B:$D, 3, TRUE) -> Månberger | D9: 80 | E9: 290
D10: 200 | E10: 250
B11: 16 | C11: =VLOOKUP(B11, Reference!$B:$D, 3, TRUE) -> Watari | D11: 210 | E11: 860
D12: 50 | E12: 210
B13: 18 | C13: =VLOOKUP(B13, Reference!$B:$D, 3, TRUE) -> Deetman | D13: 350 | E13: 630
D14: 25 | E14: 65
B15: 23 | C15: =VLOOKUP(B15, Reference!$B:$D, 3, TRUE) -> Harvey | D15: 130 | E15: 500
D16: 80 | E16: 300
B17: 34 | C17: =VLOOKUP(B17, Reference!$B:$D, 3, TRUE) -> Pehlken | D17: 65 | E17: 246
D18: 3 | E18: 6
B19: 13 | C19: =VLOOKUP(B19, Reference!$B:$D, 3, TRUE) -> Valero | D19: 230 | E19: 420 | F19: All
B20: 16 | C20: =VLOOKUP(B20, Reference!$B:$D, 3, TRUE) -> Watari | D20: 440 | E20: 1260
D21: 280 | E21: 610
B22: 23 | C22: =VLOOKUP(B22, Reference!$B:$D, 3, TRUE) -> Harvey | D22: 250 | E22: 700
D23: 200 | E23: 500

Sheet Ge
A1: Unit: kt | E1: for low-carbon technologies
E2: for all end-uses
B4: Reference number | C4: Last name of the first author | D4: 2030 | E4: 2050 | F4: End-uses
B6: 45 | C6: =VLOOKUP(B6, Reference!$B:$D, 3, TRUE) -> Elshkaki | D6: 0.3 | E6: 2.5 | F6: Solar PV
D7: 0.3 | E7: 2.5
B8: 60 | C8: =VLOOKUP(B8, Reference!$B:$D, 3, TRUE) -> Elshkaki | D8: 0.5 | E8: 2.8 | F8: All

Sheet Ga
A1: Unit: kt | E1: for low-carbon technologies
E2: for all end-uses
B4: Reference number | C4: Last name of the first author | D4: 2030 | E4: 2050 | F4: End-uses
B6: 3 | C6: =VLOOKUP(B6, Reference!$B:$D, 3, TRUE) -> Watari | D6: 0.14 | E6: 0.53 | F6: Solar PV (CIGS)
D7: 0.1 | E7: 0.24
B8: 14 | C8: =VLOOKUP(B8, Reference!$B:$D, 3, TRUE) -> Månberger | D8: 0.1 | E8: 0.28
D9: 0.02 | E9: 0.02
B10: 16 | C10: =VLOOKUP(B10, Reference!$B:$D, 3, TRUE) -> Watari | D10: 0.3 | E10: 1.2
D11: 0.01 | E11: 0.2
B12: 28 | C12: =VLOOKUP(B12, Reference!$B:$D, 3, TRUE) -> Davidsson | D12: 1.3 | E12: 1.3
D13: 0.25 | E13: 0.25
B14: 60 | C14: =VLOOKUP(B14, Reference!$B:$D, 3, TRUE) -> Elshkaki | D14: 0.05 | E14: 0.24
B15: 62 | C15: =VLOOKUP(B15, Reference!$B:$D, 3, TRUE) -> Fizaine | D15: 0.1 | E15: 0.15
B16: 16 | C16: =VLOOKUP(B16, Reference!$B:$D, 3, TRUE) -> Watari | D16: 1.2 | E16: 2.8 | F16: All
D17: 1 | E17: 1.7
B18: 39 | C18: =VLOOKUP(B18, Reference!$B:$D, 3, TRUE) -> Løvik | D18: 2.8 | E18: 5.25
D19: 0.5 | E19: 0.85
B20: 46 | C20: =VLOOKUP(B20, Reference!$B:$D, 3, TRUE) -> Kavlak | D20: 2.5

Sheet Cu
A1: Unit: kt | E1: for low-carbon technologies
E2: for all end-uses
B4: Reference number | C4: Last name of the first author | D4: 2030 | E4: 2050 | F4: End-uses
B6: 3 | C6: =VLOOKUP(B6, Reference!$B:$D, 3, TRUE) -> Watari | D6: 3823 | E6: 12492 | F6: Solar PV, Wind, CSP, Electric vehicles and Fuel cells
D7: 1676 | E7: 5100
B8: 14 | C8: =VLOOKUP(B8, Reference!$B:$D, 3, TRUE) -> Månberger | D8: 2500 | E8: 6000 | F8: Solar PV, Wind, CSP and Electric vehicles
D9: 1000 | E9: 1000
B10: 16 | C10: =VLOOKUP(B10, Reference!$B:$D, 3, TRUE) -> Watari | D10: 3500 | E10: 11000 | F10: Solar PV, Wind and Electric vehicles
D11: 1600 | E11: 4900
B12: 18 | C12: =VLOOKUP(B12, Reference!$B:$D, 3, TRUE) -> Deetman | D12: 9000 | E12: 17200 | F12: Solar PV, Wind, CSP and Electric vehicles
D13: 6500 | E13: 8230
B14: 50 | C14: =VLOOKUP(B14, Reference!$B:$D, 3, TRUE) -> Davidsson | D14: 7900 | E14: 5900 | F14: Wind
E15: 2400
B16: 16 | C16: =VLOOKUP(B16, Reference!$B:$D, 3, TRUE) -> Watari | D16: 57000 | E16: 108000 | F16: All
D17: 56000 | E17: 102000
B18: 20 | C18: =VLOOKUP(B18, Reference!$B:$D, 3, TRUE) -> de Koning | E18: 37000
E19: 27000
B20: 22 | C20: =VLOOKUP(B20, Reference!$B:$D, 3, TRUE) -> Schipper | D20: 55000 | E20: 120000
D21: 30000 | E21: 40000

Sheet Ta
A1: Unit: kt | E1: for low-carbon technologies
E2: for all end-uses
B4: Reference number | C4: Last name of the first author | D4: 2030 | E4: 2050 | F4: End-uses
B6: 13 | C6: =VLOOKUP(B6, Reference!$B:$D, 3, TRUE) -> Valero | D6: 0.3 | E6: 0.65 | F6: Electric vehicles
B7: 18 | C7: =VLOOKUP(B7, Reference!$B:$D, 3, TRUE) -> Deetman | D7: 2.3 | E7: 3.2
D8: 0.6 | E8: 0.9
B9: 13 | C9: =VLOOKUP(B9, Reference!$B:$D, 3, TRUE) -> Valero | D9: 1.5 | E9: 1.8 | F9: All
B10: 18 | C10: =VLOOKUP(B10, Reference!$B:$D, 3, TRUE) -> Deetman | D10: 4.7 | E10: 6.6
D11: 1.5 | E11: 2.2

Sheet Ni
A1: Unit: kt | E1: for low-carbon technologies
E2: for all end-uses
B4: Reference number | C4: Last name of the first author | D4: 2030 | E4: 2050 | F4: End-uses
B6: 3 | C6: =VLOOKUP(B6, Reference!$B:$D, 3, TRUE) -> Watari | D6: 833 | E6: 3394 | F6: Electric vehicles
D7: 223 | E7: 896
B8: 13 | C8: =VLOOKUP(B8, Reference!$B:$D, 3, TRUE) -> Valero | D8: 750 | E8: 2000 | F8: Solar PV, Wind, CSP and Electric vehicles
B9: 14 | C9: =VLOOKUP(B9, Reference!$B:$D, 3, TRUE) -> Månberger | D9: 1200 | E9: 4500 | F9: Wind, CSP and Electric vehicles
D10: 200 | E10: 200
B11: 16 | C11: =VLOOKUP(B11, Reference!$B:$D, 3, TRUE) -> Watari | D11: 1100 | E11: 4500 | F11: Electric vehicles
D12: 300 | E12: 1100
B13: 13 | C13: =VLOOKUP(B13, Reference!$B:$D, 3, TRUE) -> Valero | D13: 3200 | E13: 4500 | F13: All
B14: 16 | C14: =VLOOKUP(B14, Reference!$B:$D, 3, TRUE) -> Watari | D14: 4600 | E14: 10000
D15: 3800 | E15: 6600

Sheet Li
A1: Unit: kt | E1: for low-carbon technologies
E2: for all end-uses
B4: Reference number | C4: Last name of the first author | D4: 2030 | E4: 2050 | F4: End-uses
B6: 3 | C6: =VLOOKUP(B6, Reference!$B:$D, 3, TRUE) -> Watari | D6: 155.8 | E6: 666.4 | F6: Electric vehicles
D7: 34 | E7: 145.5
B8: 13 | C8: =VLOOKUP(B8, Reference!$B:$D, 3, TRUE) -> Valero | D8: 175 | E8: 390
B9: 14 | C9: =VLOOKUP(B9, Reference!$B:$D, 3, TRUE) -> Månberger | D9: 390 | E9: 1500
D10: 200 | E10: 300
B11: 16 | C11: =VLOOKUP(B11, Reference!$B:$D, 3, TRUE) -> Watari | D11: 290 | E11: 1230
D12: 61 | E12: 260
B13: 18 | C13: =VLOOKUP(B13, Reference!$B:$D, 3, TRUE) -> Deetman | D13: 440 | E13: 800
D14: 15 | E14: 52
B15: 19 | C15: =VLOOKUP(B15, Reference!$B:$D, 3, TRUE) -> Ziemann | D15: 600 | E15: 1430
D16: 100 | E16: 370
B17: 20 | C17: =VLOOKUP(B17, Reference!$B:$D, 3, TRUE) -> de Koning | E17: 414
E18: 0.4
B19: 23 | C19: =VLOOKUP(B19, Reference!$B:$D, 3, TRUE) -> Harvey | D19: 30 | E19: 290
D20: 20 | E20: 190
B21: 34 | C21: =VLOOKUP(B21, Reference!$B:$D, 3, TRUE) -> Pehlken | D21: 500 | E21: 2000
D22: 200 | E22: 370
B23: 56 | C23: =VLOOKUP(B23, Reference!$B:$D, 3, TRUE) -> Speirs | D23: 280 | E23: 1000
D24: 50 | E24: 200
B25: 64 | C25: =VLOOKUP(B25, Reference!$B:$D, 3, TRUE) -> Vikström | D25: 75 | E25: 275
B26: 70 | C26: =VLOOKUP(B26, Reference!$B:$D, 3, TRUE) -> Mohr | E26: 400
B27: 5 | C27: =VLOOKUP(B27, Reference!$B:$D, 3, TRUE) -> Hache | D27: 450 | E27: 1200 | F27: All
D28: 170 | E28: 300
B29: 13 | C29: =VLOOKUP(B29, Reference!$B:$D, 3, TRUE) -> Valero | D29: 700 | E29: 950
B30: 16 | C30: =VLOOKUP(B30, Reference!$B:$D, 3, TRUE) -> Watari | D30: 350 | E30: 1330
D31: 120 | E31: 370
B32: 19 | C32: =VLOOKUP(B32, Reference!$B:$D, 3, TRUE) -> Ziemann | D32: 700 | E32: 1630
D33: 200 | E33: 570
B34: 20 | C34: =VLOOKUP(B34, Reference!$B:$D, 3, TRUE) -> de Koning | E34: 1628
E35: 1230
B36: 23 | C36: =VLOOKUP(B36, Reference!$B:$D, 3, TRUE) -> Harvey | D36: 70 | E36: 330
D37: 60 | E37: 230
B38: 35 | C38: =VLOOKUP(B38, Reference!$B:$D, 3, TRUE) -> Ulrik Sverdrup | D38: 150 | E38: 500
B39: 64 | C39: =VLOOKUP(B39, Reference!$B:$D, 3, TRUE) -> Vikström | D39: 100 | E39: 300
B40: 71 | C40: =VLOOKUP(B40, Reference!$B:$D, 3, TRUE) -> Kushnir | D40: 450 | E40: 1400
D41: 100 | E41: 200

Sheet Si
A1: Unit: kt | E1: for low-carbon technologies
E2: for all end-uses
B4: Reference number | C4: Last name of the first author | D4: 2030 | E4: 2050 | F4: End-uses
B6: 3 | C6: =VLOOKUP(B6, Reference!$B:$D, 3, TRUE) -> Watari | D6: 699 | E6: 1832 | F6: Solar PV (c-Si)
D7: 458 | E7: 823
B8: 77 | C8: =VLOOKUP(B8, Reference!$B:$D, 3, TRUE) -> Zuser | D8: 1351
D9: 446
B10: 46 | C10: =VLOOKUP(B10, Reference!$B:$D, 3, TRUE) -> Kavlak | D10: 12200 | F10: All
